<?xml version="1.0"?>
<robot name="turtlebot_burger">
  <link name="base_link">
    <visual>
      <geometry>
        <mesh filename="package://turtlebot3_description/meshes/turtlebot3_burger_base.dae"/>
      </geometry>
    </visual>
    <collision>
      <geometry>
        <mesh filename="package://turtlebot3_description/meshes/turtlebot3_burger_base.dae"/>
      </geometry>
    </collision>
    <inertial>
      <mass value="2.5"/>
      <origin xyz="0 0 0" rpy="0 0 0"/>
      <inertia ixx="0.1" ixy="0.0" ixz="0.0" iyy="0.1" iyz="0.0" izz="0.1"/>
    </inertial>
  </link>
  <link name="wheel_left_link">
    <visual>
      <geometry>
        <mesh filename="package://turtlebot3_description/meshes/turtlebot3_burger_wheel_left.dae"/>
      </geometry>
    </visual>
    <collision>
      <geometry>
        <mesh filename="package://turtlebot3_description/meshes/turtlebot3_burger_wheel_left.dae"/>
      </geometry>
    </collision>
    <inertial>
      <mass value="0.2"/>
      <origin xyz="0 0 0" rpy="0 0 0"/>
      <inertia ixx="0.1" ixy="0.0" ixz="0.0" iyy="0.1" iyz="0.0" izz="0.1"/>
    </inertial>
  </link>
  <link name="wheel_right_link">
    <visual>
      <geometry>
        <mesh filename="package://turtlebot3_description/meshes/turtlebot3_burger_wheel_right.dae"/>
      </geometry>
    </visual>
    <collision>
      <geometry>
        <mesh filename="package://turtlebot3_description/meshes/turtlebot3_burger_wheel_right.dae"/>
      </geometry>
    </collision>
    <inertial>
      <mass value="0.2"/>
      <origin xyz="0 0 0" rpy="0 0 0"/>
      <inertia ixx="0.1" ixy="0.0" ixz="0.0" iyy="0.1" iyz="0.0" izz="0.1"/>
    </inertial>
  </link>
  <joint name="wheel_left_joint" type="continuous">
    <parent link="base_link"/>
    <child link="wheel_left_link"/>
    <origin xyz="0.1 0 0.1" rpy="0 0 0"/>
    <axis xyz="0 0 1"/>
  </joint>
  <joint name="wheel_right_joint" type="continuous">
    <parent link="base_link"/>
    <child link="wheel_right_link"/>
    <origin xyz="-0.1 0 0.1" rpy="0 0 0"/>
    <axis xyz="0 0 1"/>
  </joint>
</robot>